nohup: ignoring input
[2022-10-12 18:44:07 +0800] [4013401] [INFO] Starting gunicorn 20.1.0
[2022-10-12 18:44:07 +0800] [4013401] [INFO] Listening at: http://[::]:8793 (4013401)
[2022-10-12 18:44:07 +0800] [4013401] [INFO] Using worker: sync
[2022-10-12 18:44:07 +0800] [4013402] [INFO] Booting worker with pid: 4013402
[2022-10-12 18:44:07 +0800] [4013404] [INFO] Booting worker with pid: 4013404
[2022-10-12 19:52:13 +0800] [4013401] [INFO] Handling signal: hup
[2022-10-12 19:52:13 +0800] [4013401] [INFO] Hang up: Master
[2022-10-12 19:52:13 +0800] [4013401] [WARNING] Worker with pid 4013402 was terminated due to signal 1
[2022-10-12 19:52:13 +0800] [4013401] [WARNING] Worker with pid 4013404 was terminated due to signal 1
[2022-10-12 19:52:13 +0800] [4048042] [INFO] Booting worker with pid: 4048042
[2022-10-12 19:52:13 +0800] [4048044] [INFO] Booting worker with pid: 4048044
Process ForkProcess-35:
Traceback (most recent call last):
  File "/home/lianghua/anaconda3/envs/zirui_env/lib/python3.9/site-packages/mysql/connector/connection_cext.py", line 555, in cmd_query
    self._cmysql.query(
_mysql_connector.MySQLInterfaceError: Lost connection to MySQL server during query

The above exception was the direct cause of the following exception:

Traceback (most recent call last):
  File "/home/lianghua/anaconda3/envs/zirui_env/lib/python3.9/site-packages/sqlalchemy/engine/base.py", line 1900, in _execute_context
    self.dialect.do_execute(
  File "/home/lianghua/anaconda3/envs/zirui_env/lib/python3.9/site-packages/sqlalchemy/engine/default.py", line 736, in do_execute
    cursor.execute(statement, parameters)
  File "/home/lianghua/anaconda3/envs/zirui_env/lib/python3.9/site-packages/mysql/connector/cursor_cext.py", line 276, in execute
    result = self._cnx.cmd_query(
  File "/home/lianghua/anaconda3/envs/zirui_env/lib/python3.9/site-packages/mysql/connector/connection_cext.py", line 563, in cmd_query
    raise get_mysql_exception(
mysql.connector.errors.OperationalError: 2013 (HY000): Lost connection to MySQL server during query

The above exception was the direct cause of the following exception:

Traceback (most recent call last):
  File "/home/lianghua/anaconda3/envs/zirui_env/lib/python3.9/multiprocessing/process.py", line 315, in _bootstrap
    self.run()
  File "/home/lianghua/anaconda3/envs/zirui_env/lib/python3.9/multiprocessing/process.py", line 108, in run
    self._target(*self._args, **self._kwargs)
  File "/home/lianghua/anaconda3/envs/zirui_env/lib/python3.9/site-packages/airflow/dag_processing/manager.py", line 257, in _run_processor_manager
    processor_manager.start()
  File "/home/lianghua/anaconda3/envs/zirui_env/lib/python3.9/site-packages/airflow/dag_processing/manager.py", line 489, in start
    return self._run_parsing_loop()
  File "/home/lianghua/anaconda3/envs/zirui_env/lib/python3.9/site-packages/airflow/dag_processing/manager.py", line 603, in _run_parsing_loop
    DagWarning.purge_inactive_dag_warnings()
  File "/home/lianghua/anaconda3/envs/zirui_env/lib/python3.9/site-packages/airflow/utils/session.py", line 75, in wrapper
    return func(*args, session=session, **kwargs)
  File "/home/lianghua/anaconda3/envs/zirui_env/lib/python3.9/site-packages/airflow/models/dagwarning.py", line 82, in purge_inactive_dag_warnings
    query.delete(synchronize_session=False)
  File "/home/lianghua/anaconda3/envs/zirui_env/lib/python3.9/site-packages/sqlalchemy/orm/query.py", line 3213, in delete
    result = self.session.execute(
  File "/home/lianghua/anaconda3/envs/zirui_env/lib/python3.9/site-packages/sqlalchemy/orm/session.py", line 1712, in execute
    result = conn._execute_20(statement, params or {}, execution_options)
  File "/home/lianghua/anaconda3/envs/zirui_env/lib/python3.9/site-packages/sqlalchemy/engine/base.py", line 1705, in _execute_20
    return meth(self, args_10style, kwargs_10style, execution_options)
  File "/home/lianghua/anaconda3/envs/zirui_env/lib/python3.9/site-packages/sqlalchemy/sql/elements.py", line 333, in _execute_on_connection
    return connection._execute_clauseelement(
  File "/home/lianghua/anaconda3/envs/zirui_env/lib/python3.9/site-packages/sqlalchemy/engine/base.py", line 1572, in _execute_clauseelement
    ret = self._execute_context(
  File "/home/lianghua/anaconda3/envs/zirui_env/lib/python3.9/site-packages/sqlalchemy/engine/base.py", line 1943, in _execute_context
    self._handle_dbapi_exception(
  File "/home/lianghua/anaconda3/envs/zirui_env/lib/python3.9/site-packages/sqlalchemy/engine/base.py", line 2124, in _handle_dbapi_exception
    util.raise_(
  File "/home/lianghua/anaconda3/envs/zirui_env/lib/python3.9/site-packages/sqlalchemy/util/compat.py", line 208, in raise_
    raise exception
  File "/home/lianghua/anaconda3/envs/zirui_env/lib/python3.9/site-packages/sqlalchemy/engine/base.py", line 1900, in _execute_context
    self.dialect.do_execute(
  File "/home/lianghua/anaconda3/envs/zirui_env/lib/python3.9/site-packages/sqlalchemy/engine/default.py", line 736, in do_execute
    cursor.execute(statement, parameters)
  File "/home/lianghua/anaconda3/envs/zirui_env/lib/python3.9/site-packages/mysql/connector/cursor_cext.py", line 276, in execute
    result = self._cnx.cmd_query(
  File "/home/lianghua/anaconda3/envs/zirui_env/lib/python3.9/site-packages/mysql/connector/connection_cext.py", line 563, in cmd_query
    raise get_mysql_exception(
sqlalchemy.exc.OperationalError: (mysql.connector.errors.OperationalError) 2013 (HY000): Lost connection to MySQL server during query
[SQL: DELETE FROM dag_warning USING dag_warning, dag WHERE dag_warning.dag_id = dag.dag_id AND dag.is_active = false]
(Background on this error at: https://sqlalche.me/e/14/e3q8)
Process ForkProcess-36:
Traceback (most recent call last):
  File "/home/lianghua/anaconda3/envs/zirui_env/lib/python3.9/site-packages/mysql/connector/connection_cext.py", line 555, in cmd_query
    self._cmysql.query(
_mysql_connector.MySQLInterfaceError: Lost connection to MySQL server during query

The above exception was the direct cause of the following exception:

Traceback (most recent call last):
  File "/home/lianghua/anaconda3/envs/zirui_env/lib/python3.9/site-packages/sqlalchemy/engine/base.py", line 1900, in _execute_context
    self.dialect.do_execute(
  File "/home/lianghua/anaconda3/envs/zirui_env/lib/python3.9/site-packages/sqlalchemy/engine/default.py", line 736, in do_execute
    cursor.execute(statement, parameters)
  File "/home/lianghua/anaconda3/envs/zirui_env/lib/python3.9/site-packages/mysql/connector/cursor_cext.py", line 276, in execute
    result = self._cnx.cmd_query(
  File "/home/lianghua/anaconda3/envs/zirui_env/lib/python3.9/site-packages/mysql/connector/connection_cext.py", line 563, in cmd_query
    raise get_mysql_exception(
mysql.connector.errors.OperationalError: 2013 (HY000): Lost connection to MySQL server during query

The above exception was the direct cause of the following exception:

Traceback (most recent call last):
  File "/home/lianghua/anaconda3/envs/zirui_env/lib/python3.9/multiprocessing/process.py", line 315, in _bootstrap
    self.run()
  File "/home/lianghua/anaconda3/envs/zirui_env/lib/python3.9/multiprocessing/process.py", line 108, in run
    self._target(*self._args, **self._kwargs)
  File "/home/lianghua/anaconda3/envs/zirui_env/lib/python3.9/site-packages/airflow/dag_processing/manager.py", line 257, in _run_processor_manager
    processor_manager.start()
  File "/home/lianghua/anaconda3/envs/zirui_env/lib/python3.9/site-packages/airflow/dag_processing/manager.py", line 489, in start
    return self._run_parsing_loop()
  File "/home/lianghua/anaconda3/envs/zirui_env/lib/python3.9/site-packages/airflow/dag_processing/manager.py", line 603, in _run_parsing_loop
    DagWarning.purge_inactive_dag_warnings()
  File "/home/lianghua/anaconda3/envs/zirui_env/lib/python3.9/site-packages/airflow/utils/session.py", line 75, in wrapper
    return func(*args, session=session, **kwargs)
  File "/home/lianghua/anaconda3/envs/zirui_env/lib/python3.9/site-packages/airflow/models/dagwarning.py", line 82, in purge_inactive_dag_warnings
    query.delete(synchronize_session=False)
  File "/home/lianghua/anaconda3/envs/zirui_env/lib/python3.9/site-packages/sqlalchemy/orm/query.py", line 3213, in delete
    result = self.session.execute(
  File "/home/lianghua/anaconda3/envs/zirui_env/lib/python3.9/site-packages/sqlalchemy/orm/session.py", line 1712, in execute
    result = conn._execute_20(statement, params or {}, execution_options)
  File "/home/lianghua/anaconda3/envs/zirui_env/lib/python3.9/site-packages/sqlalchemy/engine/base.py", line 1705, in _execute_20
    return meth(self, args_10style, kwargs_10style, execution_options)
  File "/home/lianghua/anaconda3/envs/zirui_env/lib/python3.9/site-packages/sqlalchemy/sql/elements.py", line 333, in _execute_on_connection
    return connection._execute_clauseelement(
  File "/home/lianghua/anaconda3/envs/zirui_env/lib/python3.9/site-packages/sqlalchemy/engine/base.py", line 1572, in _execute_clauseelement
    ret = self._execute_context(
  File "/home/lianghua/anaconda3/envs/zirui_env/lib/python3.9/site-packages/sqlalchemy/engine/base.py", line 1943, in _execute_context
    self._handle_dbapi_exception(
  File "/home/lianghua/anaconda3/envs/zirui_env/lib/python3.9/site-packages/sqlalchemy/engine/base.py", line 2124, in _handle_dbapi_exception
    util.raise_(
  File "/home/lianghua/anaconda3/envs/zirui_env/lib/python3.9/site-packages/sqlalchemy/util/compat.py", line 208, in raise_
    raise exception
  File "/home/lianghua/anaconda3/envs/zirui_env/lib/python3.9/site-packages/sqlalchemy/engine/base.py", line 1900, in _execute_context
    self.dialect.do_execute(
  File "/home/lianghua/anaconda3/envs/zirui_env/lib/python3.9/site-packages/sqlalchemy/engine/default.py", line 736, in do_execute
    cursor.execute(statement, parameters)
  File "/home/lianghua/anaconda3/envs/zirui_env/lib/python3.9/site-packages/mysql/connector/cursor_cext.py", line 276, in execute
    result = self._cnx.cmd_query(
  File "/home/lianghua/anaconda3/envs/zirui_env/lib/python3.9/site-packages/mysql/connector/connection_cext.py", line 563, in cmd_query
    raise get_mysql_exception(
sqlalchemy.exc.OperationalError: (mysql.connector.errors.OperationalError) 2013 (HY000): Lost connection to MySQL server during query
[SQL: DELETE FROM dag_warning USING dag_warning, dag WHERE dag_warning.dag_id = dag.dag_id AND dag.is_active = false]
(Background on this error at: https://sqlalche.me/e/14/e3q8)
Process ForkProcess-37:
Traceback (most recent call last):
  File "/home/lianghua/anaconda3/envs/zirui_env/lib/python3.9/site-packages/sqlalchemy/engine/base.py", line 1800, in _execute_context
    context = constructor(
  File "/home/lianghua/anaconda3/envs/zirui_env/lib/python3.9/site-packages/sqlalchemy/engine/default.py", line 1019, in _init_compiled
    self.cursor = self.create_cursor()
  File "/home/lianghua/anaconda3/envs/zirui_env/lib/python3.9/site-packages/sqlalchemy/engine/default.py", line 1390, in create_cursor
    return self.create_default_cursor()
  File "/home/lianghua/anaconda3/envs/zirui_env/lib/python3.9/site-packages/sqlalchemy/engine/default.py", line 1393, in create_default_cursor
    return self._dbapi_connection.cursor()
  File "/home/lianghua/anaconda3/envs/zirui_env/lib/python3.9/site-packages/sqlalchemy/pool/base.py", line 1099, in cursor
    return self.dbapi_connection.cursor(*args, **kwargs)
  File "/home/lianghua/anaconda3/envs/zirui_env/lib/python3.9/site-packages/mysql/connector/connection_cext.py", line 622, in cursor
    raise OperationalError("MySQL Connection not available.")
mysql.connector.errors.OperationalError: MySQL Connection not available.

The above exception was the direct cause of the following exception:

Traceback (most recent call last):
  File "/home/lianghua/anaconda3/envs/zirui_env/lib/python3.9/multiprocessing/process.py", line 315, in _bootstrap
    self.run()
  File "/home/lianghua/anaconda3/envs/zirui_env/lib/python3.9/multiprocessing/process.py", line 108, in run
    self._target(*self._args, **self._kwargs)
  File "/home/lianghua/anaconda3/envs/zirui_env/lib/python3.9/site-packages/airflow/dag_processing/manager.py", line 257, in _run_processor_manager
    processor_manager.start()
  File "/home/lianghua/anaconda3/envs/zirui_env/lib/python3.9/site-packages/airflow/dag_processing/manager.py", line 489, in start
    return self._run_parsing_loop()
  File "/home/lianghua/anaconda3/envs/zirui_env/lib/python3.9/site-packages/airflow/dag_processing/manager.py", line 603, in _run_parsing_loop
    DagWarning.purge_inactive_dag_warnings()
  File "/home/lianghua/anaconda3/envs/zirui_env/lib/python3.9/site-packages/airflow/utils/session.py", line 75, in wrapper
    return func(*args, session=session, **kwargs)
  File "/home/lianghua/anaconda3/envs/zirui_env/lib/python3.9/site-packages/airflow/models/dagwarning.py", line 82, in purge_inactive_dag_warnings
    query.delete(synchronize_session=False)
  File "/home/lianghua/anaconda3/envs/zirui_env/lib/python3.9/site-packages/sqlalchemy/orm/query.py", line 3213, in delete
    result = self.session.execute(
  File "/home/lianghua/anaconda3/envs/zirui_env/lib/python3.9/site-packages/sqlalchemy/orm/session.py", line 1712, in execute
    result = conn._execute_20(statement, params or {}, execution_options)
  File "/home/lianghua/anaconda3/envs/zirui_env/lib/python3.9/site-packages/sqlalchemy/engine/base.py", line 1705, in _execute_20
    return meth(self, args_10style, kwargs_10style, execution_options)
  File "/home/lianghua/anaconda3/envs/zirui_env/lib/python3.9/site-packages/sqlalchemy/sql/elements.py", line 333, in _execute_on_connection
    return connection._execute_clauseelement(
  File "/home/lianghua/anaconda3/envs/zirui_env/lib/python3.9/site-packages/sqlalchemy/engine/base.py", line 1572, in _execute_clauseelement
    ret = self._execute_context(
  File "/home/lianghua/anaconda3/envs/zirui_env/lib/python3.9/site-packages/sqlalchemy/engine/base.py", line 1806, in _execute_context
    self._handle_dbapi_exception(
  File "/home/lianghua/anaconda3/envs/zirui_env/lib/python3.9/site-packages/sqlalchemy/engine/base.py", line 2124, in _handle_dbapi_exception
    util.raise_(
  File "/home/lianghua/anaconda3/envs/zirui_env/lib/python3.9/site-packages/sqlalchemy/util/compat.py", line 208, in raise_
    raise exception
  File "/home/lianghua/anaconda3/envs/zirui_env/lib/python3.9/site-packages/sqlalchemy/engine/base.py", line 1800, in _execute_context
    context = constructor(
  File "/home/lianghua/anaconda3/envs/zirui_env/lib/python3.9/site-packages/sqlalchemy/engine/default.py", line 1019, in _init_compiled
    self.cursor = self.create_cursor()
  File "/home/lianghua/anaconda3/envs/zirui_env/lib/python3.9/site-packages/sqlalchemy/engine/default.py", line 1390, in create_cursor
    return self.create_default_cursor()
  File "/home/lianghua/anaconda3/envs/zirui_env/lib/python3.9/site-packages/sqlalchemy/engine/default.py", line 1393, in create_default_cursor
    return self._dbapi_connection.cursor()
  File "/home/lianghua/anaconda3/envs/zirui_env/lib/python3.9/site-packages/sqlalchemy/pool/base.py", line 1099, in cursor
    return self.dbapi_connection.cursor(*args, **kwargs)
  File "/home/lianghua/anaconda3/envs/zirui_env/lib/python3.9/site-packages/mysql/connector/connection_cext.py", line 622, in cursor
    raise OperationalError("MySQL Connection not available.")
sqlalchemy.exc.OperationalError: (mysql.connector.errors.OperationalError) MySQL Connection not available.
[SQL: DELETE FROM dag_warning USING dag_warning, dag WHERE dag_warning.dag_id = dag.dag_id AND dag.is_active = false]
[parameters: [{}]]
(Background on this error at: https://sqlalche.me/e/14/e3q8)
Process ForkProcess-38:
Traceback (most recent call last):
  File "/home/lianghua/anaconda3/envs/zirui_env/lib/python3.9/site-packages/mysql/connector/connection_cext.py", line 555, in cmd_query
    self._cmysql.query(
_mysql_connector.MySQLInterfaceError: Lost connection to MySQL server during query

The above exception was the direct cause of the following exception:

Traceback (most recent call last):
  File "/home/lianghua/anaconda3/envs/zirui_env/lib/python3.9/site-packages/sqlalchemy/engine/base.py", line 1900, in _execute_context
    self.dialect.do_execute(
  File "/home/lianghua/anaconda3/envs/zirui_env/lib/python3.9/site-packages/sqlalchemy/engine/default.py", line 736, in do_execute
    cursor.execute(statement, parameters)
  File "/home/lianghua/anaconda3/envs/zirui_env/lib/python3.9/site-packages/mysql/connector/cursor_cext.py", line 276, in execute
    result = self._cnx.cmd_query(
  File "/home/lianghua/anaconda3/envs/zirui_env/lib/python3.9/site-packages/mysql/connector/connection_cext.py", line 563, in cmd_query
    raise get_mysql_exception(
mysql.connector.errors.OperationalError: 2013 (HY000): Lost connection to MySQL server during query

The above exception was the direct cause of the following exception:

Traceback (most recent call last):
  File "/home/lianghua/anaconda3/envs/zirui_env/lib/python3.9/multiprocessing/process.py", line 315, in _bootstrap
    self.run()
  File "/home/lianghua/anaconda3/envs/zirui_env/lib/python3.9/multiprocessing/process.py", line 108, in run
    self._target(*self._args, **self._kwargs)
  File "/home/lianghua/anaconda3/envs/zirui_env/lib/python3.9/site-packages/airflow/dag_processing/manager.py", line 257, in _run_processor_manager
    processor_manager.start()
  File "/home/lianghua/anaconda3/envs/zirui_env/lib/python3.9/site-packages/airflow/dag_processing/manager.py", line 489, in start
    return self._run_parsing_loop()
  File "/home/lianghua/anaconda3/envs/zirui_env/lib/python3.9/site-packages/airflow/dag_processing/manager.py", line 603, in _run_parsing_loop
    DagWarning.purge_inactive_dag_warnings()
  File "/home/lianghua/anaconda3/envs/zirui_env/lib/python3.9/site-packages/airflow/utils/session.py", line 75, in wrapper
    return func(*args, session=session, **kwargs)
  File "/home/lianghua/anaconda3/envs/zirui_env/lib/python3.9/site-packages/airflow/models/dagwarning.py", line 82, in purge_inactive_dag_warnings
    query.delete(synchronize_session=False)
  File "/home/lianghua/anaconda3/envs/zirui_env/lib/python3.9/site-packages/sqlalchemy/orm/query.py", line 3213, in delete
    result = self.session.execute(
  File "/home/lianghua/anaconda3/envs/zirui_env/lib/python3.9/site-packages/sqlalchemy/orm/session.py", line 1712, in execute
    result = conn._execute_20(statement, params or {}, execution_options)
  File "/home/lianghua/anaconda3/envs/zirui_env/lib/python3.9/site-packages/sqlalchemy/engine/base.py", line 1705, in _execute_20
    return meth(self, args_10style, kwargs_10style, execution_options)
  File "/home/lianghua/anaconda3/envs/zirui_env/lib/python3.9/site-packages/sqlalchemy/sql/elements.py", line 333, in _execute_on_connection
    return connection._execute_clauseelement(
  File "/home/lianghua/anaconda3/envs/zirui_env/lib/python3.9/site-packages/sqlalchemy/engine/base.py", line 1572, in _execute_clauseelement
    ret = self._execute_context(
  File "/home/lianghua/anaconda3/envs/zirui_env/lib/python3.9/site-packages/sqlalchemy/engine/base.py", line 1943, in _execute_context
    self._handle_dbapi_exception(
  File "/home/lianghua/anaconda3/envs/zirui_env/lib/python3.9/site-packages/sqlalchemy/engine/base.py", line 2124, in _handle_dbapi_exception
    util.raise_(
  File "/home/lianghua/anaconda3/envs/zirui_env/lib/python3.9/site-packages/sqlalchemy/util/compat.py", line 208, in raise_
    raise exception
  File "/home/lianghua/anaconda3/envs/zirui_env/lib/python3.9/site-packages/sqlalchemy/engine/base.py", line 1900, in _execute_context
    self.dialect.do_execute(
  File "/home/lianghua/anaconda3/envs/zirui_env/lib/python3.9/site-packages/sqlalchemy/engine/default.py", line 736, in do_execute
    cursor.execute(statement, parameters)
  File "/home/lianghua/anaconda3/envs/zirui_env/lib/python3.9/site-packages/mysql/connector/cursor_cext.py", line 276, in execute
    result = self._cnx.cmd_query(
  File "/home/lianghua/anaconda3/envs/zirui_env/lib/python3.9/site-packages/mysql/connector/connection_cext.py", line 563, in cmd_query
    raise get_mysql_exception(
sqlalchemy.exc.OperationalError: (mysql.connector.errors.OperationalError) 2013 (HY000): Lost connection to MySQL server during query
[SQL: DELETE FROM dag_warning USING dag_warning, dag WHERE dag_warning.dag_id = dag.dag_id AND dag.is_active = false]
(Background on this error at: https://sqlalche.me/e/14/e3q8)
Process ForkProcess-39:
Traceback (most recent call last):
  File "/home/lianghua/anaconda3/envs/zirui_env/lib/python3.9/site-packages/mysql/connector/connection_cext.py", line 555, in cmd_query
    self._cmysql.query(
_mysql_connector.MySQLInterfaceError: Lost connection to MySQL server during query

The above exception was the direct cause of the following exception:

Traceback (most recent call last):
  File "/home/lianghua/anaconda3/envs/zirui_env/lib/python3.9/site-packages/sqlalchemy/engine/base.py", line 1900, in _execute_context
    self.dialect.do_execute(
  File "/home/lianghua/anaconda3/envs/zirui_env/lib/python3.9/site-packages/sqlalchemy/engine/default.py", line 736, in do_execute
    cursor.execute(statement, parameters)
  File "/home/lianghua/anaconda3/envs/zirui_env/lib/python3.9/site-packages/mysql/connector/cursor_cext.py", line 276, in execute
    result = self._cnx.cmd_query(
  File "/home/lianghua/anaconda3/envs/zirui_env/lib/python3.9/site-packages/mysql/connector/connection_cext.py", line 563, in cmd_query
    raise get_mysql_exception(
mysql.connector.errors.OperationalError: 2013 (HY000): Lost connection to MySQL server during query

The above exception was the direct cause of the following exception:

Traceback (most recent call last):
  File "/home/lianghua/anaconda3/envs/zirui_env/lib/python3.9/multiprocessing/process.py", line 315, in _bootstrap
    self.run()
  File "/home/lianghua/anaconda3/envs/zirui_env/lib/python3.9/multiprocessing/process.py", line 108, in run
    self._target(*self._args, **self._kwargs)
  File "/home/lianghua/anaconda3/envs/zirui_env/lib/python3.9/site-packages/airflow/dag_processing/manager.py", line 257, in _run_processor_manager
    processor_manager.start()
  File "/home/lianghua/anaconda3/envs/zirui_env/lib/python3.9/site-packages/airflow/dag_processing/manager.py", line 489, in start
    return self._run_parsing_loop()
  File "/home/lianghua/anaconda3/envs/zirui_env/lib/python3.9/site-packages/airflow/dag_processing/manager.py", line 603, in _run_parsing_loop
    DagWarning.purge_inactive_dag_warnings()
  File "/home/lianghua/anaconda3/envs/zirui_env/lib/python3.9/site-packages/airflow/utils/session.py", line 75, in wrapper
    return func(*args, session=session, **kwargs)
  File "/home/lianghua/anaconda3/envs/zirui_env/lib/python3.9/site-packages/airflow/models/dagwarning.py", line 82, in purge_inactive_dag_warnings
    query.delete(synchronize_session=False)
  File "/home/lianghua/anaconda3/envs/zirui_env/lib/python3.9/site-packages/sqlalchemy/orm/query.py", line 3213, in delete
    result = self.session.execute(
  File "/home/lianghua/anaconda3/envs/zirui_env/lib/python3.9/site-packages/sqlalchemy/orm/session.py", line 1712, in execute
    result = conn._execute_20(statement, params or {}, execution_options)
  File "/home/lianghua/anaconda3/envs/zirui_env/lib/python3.9/site-packages/sqlalchemy/engine/base.py", line 1705, in _execute_20
    return meth(self, args_10style, kwargs_10style, execution_options)
  File "/home/lianghua/anaconda3/envs/zirui_env/lib/python3.9/site-packages/sqlalchemy/sql/elements.py", line 333, in _execute_on_connection
    return connection._execute_clauseelement(
  File "/home/lianghua/anaconda3/envs/zirui_env/lib/python3.9/site-packages/sqlalchemy/engine/base.py", line 1572, in _execute_clauseelement
    ret = self._execute_context(
  File "/home/lianghua/anaconda3/envs/zirui_env/lib/python3.9/site-packages/sqlalchemy/engine/base.py", line 1943, in _execute_context
    self._handle_dbapi_exception(
  File "/home/lianghua/anaconda3/envs/zirui_env/lib/python3.9/site-packages/sqlalchemy/engine/base.py", line 2124, in _handle_dbapi_exception
    util.raise_(
  File "/home/lianghua/anaconda3/envs/zirui_env/lib/python3.9/site-packages/sqlalchemy/util/compat.py", line 208, in raise_
    raise exception
  File "/home/lianghua/anaconda3/envs/zirui_env/lib/python3.9/site-packages/sqlalchemy/engine/base.py", line 1900, in _execute_context
    self.dialect.do_execute(
  File "/home/lianghua/anaconda3/envs/zirui_env/lib/python3.9/site-packages/sqlalchemy/engine/default.py", line 736, in do_execute
    cursor.execute(statement, parameters)
  File "/home/lianghua/anaconda3/envs/zirui_env/lib/python3.9/site-packages/mysql/connector/cursor_cext.py", line 276, in execute
    result = self._cnx.cmd_query(
  File "/home/lianghua/anaconda3/envs/zirui_env/lib/python3.9/site-packages/mysql/connector/connection_cext.py", line 563, in cmd_query
    raise get_mysql_exception(
sqlalchemy.exc.OperationalError: (mysql.connector.errors.OperationalError) 2013 (HY000): Lost connection to MySQL server during query
[SQL: DELETE FROM dag_warning USING dag_warning, dag WHERE dag_warning.dag_id = dag.dag_id AND dag.is_active = false]
(Background on this error at: https://sqlalche.me/e/14/e3q8)
Process ForkProcess-40:
Traceback (most recent call last):
  File "/home/lianghua/anaconda3/envs/zirui_env/lib/python3.9/site-packages/mysql/connector/connection_cext.py", line 555, in cmd_query
    self._cmysql.query(
_mysql_connector.MySQLInterfaceError: Lost connection to MySQL server during query

The above exception was the direct cause of the following exception:

Traceback (most recent call last):
  File "/home/lianghua/anaconda3/envs/zirui_env/lib/python3.9/site-packages/sqlalchemy/engine/base.py", line 1900, in _execute_context
    self.dialect.do_execute(
  File "/home/lianghua/anaconda3/envs/zirui_env/lib/python3.9/site-packages/sqlalchemy/engine/default.py", line 736, in do_execute
    cursor.execute(statement, parameters)
  File "/home/lianghua/anaconda3/envs/zirui_env/lib/python3.9/site-packages/mysql/connector/cursor_cext.py", line 276, in execute
    result = self._cnx.cmd_query(
  File "/home/lianghua/anaconda3/envs/zirui_env/lib/python3.9/site-packages/mysql/connector/connection_cext.py", line 563, in cmd_query
    raise get_mysql_exception(
mysql.connector.errors.OperationalError: 2013 (HY000): Lost connection to MySQL server during query

The above exception was the direct cause of the following exception:

Traceback (most recent call last):
  File "/home/lianghua/anaconda3/envs/zirui_env/lib/python3.9/multiprocessing/process.py", line 315, in _bootstrap
    self.run()
  File "/home/lianghua/anaconda3/envs/zirui_env/lib/python3.9/multiprocessing/process.py", line 108, in run
    self._target(*self._args, **self._kwargs)
  File "/home/lianghua/anaconda3/envs/zirui_env/lib/python3.9/site-packages/airflow/dag_processing/manager.py", line 257, in _run_processor_manager
    processor_manager.start()
  File "/home/lianghua/anaconda3/envs/zirui_env/lib/python3.9/site-packages/airflow/dag_processing/manager.py", line 489, in start
    return self._run_parsing_loop()
  File "/home/lianghua/anaconda3/envs/zirui_env/lib/python3.9/site-packages/airflow/dag_processing/manager.py", line 603, in _run_parsing_loop
    DagWarning.purge_inactive_dag_warnings()
  File "/home/lianghua/anaconda3/envs/zirui_env/lib/python3.9/site-packages/airflow/utils/session.py", line 75, in wrapper
    return func(*args, session=session, **kwargs)
  File "/home/lianghua/anaconda3/envs/zirui_env/lib/python3.9/site-packages/airflow/models/dagwarning.py", line 82, in purge_inactive_dag_warnings
    query.delete(synchronize_session=False)
  File "/home/lianghua/anaconda3/envs/zirui_env/lib/python3.9/site-packages/sqlalchemy/orm/query.py", line 3213, in delete
    result = self.session.execute(
  File "/home/lianghua/anaconda3/envs/zirui_env/lib/python3.9/site-packages/sqlalchemy/orm/session.py", line 1712, in execute
    result = conn._execute_20(statement, params or {}, execution_options)
  File "/home/lianghua/anaconda3/envs/zirui_env/lib/python3.9/site-packages/sqlalchemy/engine/base.py", line 1705, in _execute_20
    return meth(self, args_10style, kwargs_10style, execution_options)
  File "/home/lianghua/anaconda3/envs/zirui_env/lib/python3.9/site-packages/sqlalchemy/sql/elements.py", line 333, in _execute_on_connection
    return connection._execute_clauseelement(
  File "/home/lianghua/anaconda3/envs/zirui_env/lib/python3.9/site-packages/sqlalchemy/engine/base.py", line 1572, in _execute_clauseelement
    ret = self._execute_context(
  File "/home/lianghua/anaconda3/envs/zirui_env/lib/python3.9/site-packages/sqlalchemy/engine/base.py", line 1943, in _execute_context
    self._handle_dbapi_exception(
  File "/home/lianghua/anaconda3/envs/zirui_env/lib/python3.9/site-packages/sqlalchemy/engine/base.py", line 2124, in _handle_dbapi_exception
    util.raise_(
  File "/home/lianghua/anaconda3/envs/zirui_env/lib/python3.9/site-packages/sqlalchemy/util/compat.py", line 208, in raise_
    raise exception
  File "/home/lianghua/anaconda3/envs/zirui_env/lib/python3.9/site-packages/sqlalchemy/engine/base.py", line 1900, in _execute_context
    self.dialect.do_execute(
  File "/home/lianghua/anaconda3/envs/zirui_env/lib/python3.9/site-packages/sqlalchemy/engine/default.py", line 736, in do_execute
    cursor.execute(statement, parameters)
  File "/home/lianghua/anaconda3/envs/zirui_env/lib/python3.9/site-packages/mysql/connector/cursor_cext.py", line 276, in execute
    result = self._cnx.cmd_query(
  File "/home/lianghua/anaconda3/envs/zirui_env/lib/python3.9/site-packages/mysql/connector/connection_cext.py", line 563, in cmd_query
    raise get_mysql_exception(
sqlalchemy.exc.OperationalError: (mysql.connector.errors.OperationalError) 2013 (HY000): Lost connection to MySQL server during query
[SQL: DELETE FROM dag_warning USING dag_warning, dag WHERE dag_warning.dag_id = dag.dag_id AND dag.is_active = false]
(Background on this error at: https://sqlalche.me/e/14/e3q8)
Process ForkProcess-41:
Traceback (most recent call last):
  File "/home/lianghua/anaconda3/envs/zirui_env/lib/python3.9/multiprocessing/process.py", line 315, in _bootstrap
    self.run()
  File "/home/lianghua/anaconda3/envs/zirui_env/lib/python3.9/multiprocessing/process.py", line 108, in run
    self._target(*self._args, **self._kwargs)
  File "/home/lianghua/anaconda3/envs/zirui_env/lib/python3.9/site-packages/airflow/dag_processing/manager.py", line 257, in _run_processor_manager
    processor_manager.start()
  File "/home/lianghua/anaconda3/envs/zirui_env/lib/python3.9/site-packages/airflow/dag_processing/manager.py", line 489, in start
    return self._run_parsing_loop()
  File "/home/lianghua/anaconda3/envs/zirui_env/lib/python3.9/site-packages/airflow/dag_processing/manager.py", line 603, in _run_parsing_loop
    DagWarning.purge_inactive_dag_warnings()
  File "/home/lianghua/anaconda3/envs/zirui_env/lib/python3.9/site-packages/airflow/utils/session.py", line 75, in wrapper
    return func(*args, session=session, **kwargs)
  File "/home/lianghua/anaconda3/envs/zirui_env/lib/python3.9/site-packages/airflow/models/dagwarning.py", line 83, in purge_inactive_dag_warnings
    session.commit()
  File "/home/lianghua/anaconda3/envs/zirui_env/lib/python3.9/site-packages/sqlalchemy/orm/session.py", line 1451, in commit
    self._transaction.commit(_to_root=self.future)
  File "/home/lianghua/anaconda3/envs/zirui_env/lib/python3.9/site-packages/sqlalchemy/orm/session.py", line 836, in commit
    trans.commit()
  File "/home/lianghua/anaconda3/envs/zirui_env/lib/python3.9/site-packages/sqlalchemy/engine/base.py", line 2459, in commit
    self._do_commit()
  File "/home/lianghua/anaconda3/envs/zirui_env/lib/python3.9/site-packages/sqlalchemy/engine/base.py", line 2649, in _do_commit
    self._connection_commit_impl()
  File "/home/lianghua/anaconda3/envs/zirui_env/lib/python3.9/site-packages/sqlalchemy/engine/base.py", line 2620, in _connection_commit_impl
    self.connection._commit_impl()
  File "/home/lianghua/anaconda3/envs/zirui_env/lib/python3.9/site-packages/sqlalchemy/engine/base.py", line 1091, in _commit_impl
    self._handle_dbapi_exception(e, None, None, None, None)
  File "/home/lianghua/anaconda3/envs/zirui_env/lib/python3.9/site-packages/sqlalchemy/engine/base.py", line 2128, in _handle_dbapi_exception
    util.raise_(exc_info[1], with_traceback=exc_info[2])
  File "/home/lianghua/anaconda3/envs/zirui_env/lib/python3.9/site-packages/sqlalchemy/util/compat.py", line 208, in raise_
    raise exception
  File "/home/lianghua/anaconda3/envs/zirui_env/lib/python3.9/site-packages/sqlalchemy/engine/base.py", line 1089, in _commit_impl
    self.engine.dialect.do_commit(self.connection)
  File "/home/lianghua/anaconda3/envs/zirui_env/lib/python3.9/site-packages/sqlalchemy/engine/default.py", line 686, in do_commit
    dbapi_connection.commit()
  File "/home/lianghua/anaconda3/envs/zirui_env/lib/python3.9/site-packages/mysql/connector/connection_cext.py", line 444, in commit
    self._cmysql.commit()
_mysql_connector.MySQLInterfaceError: Lost connection to MySQL server during query
Process ForkProcess-42:
Traceback (most recent call last):
  File "/home/lianghua/anaconda3/envs/zirui_env/lib/python3.9/site-packages/sqlalchemy/engine/base.py", line 1800, in _execute_context
    context = constructor(
  File "/home/lianghua/anaconda3/envs/zirui_env/lib/python3.9/site-packages/sqlalchemy/engine/default.py", line 1019, in _init_compiled
    self.cursor = self.create_cursor()
  File "/home/lianghua/anaconda3/envs/zirui_env/lib/python3.9/site-packages/sqlalchemy/engine/default.py", line 1390, in create_cursor
    return self.create_default_cursor()
  File "/home/lianghua/anaconda3/envs/zirui_env/lib/python3.9/site-packages/sqlalchemy/engine/default.py", line 1393, in create_default_cursor
    return self._dbapi_connection.cursor()
  File "/home/lianghua/anaconda3/envs/zirui_env/lib/python3.9/site-packages/sqlalchemy/pool/base.py", line 1099, in cursor
    return self.dbapi_connection.cursor(*args, **kwargs)
  File "/home/lianghua/anaconda3/envs/zirui_env/lib/python3.9/site-packages/mysql/connector/connection_cext.py", line 622, in cursor
    raise OperationalError("MySQL Connection not available.")
mysql.connector.errors.OperationalError: MySQL Connection not available.

The above exception was the direct cause of the following exception:

Traceback (most recent call last):
  File "/home/lianghua/anaconda3/envs/zirui_env/lib/python3.9/multiprocessing/process.py", line 315, in _bootstrap
    self.run()
  File "/home/lianghua/anaconda3/envs/zirui_env/lib/python3.9/multiprocessing/process.py", line 108, in run
    self._target(*self._args, **self._kwargs)
  File "/home/lianghua/anaconda3/envs/zirui_env/lib/python3.9/site-packages/airflow/dag_processing/manager.py", line 257, in _run_processor_manager
    processor_manager.start()
  File "/home/lianghua/anaconda3/envs/zirui_env/lib/python3.9/site-packages/airflow/dag_processing/manager.py", line 489, in start
    return self._run_parsing_loop()
  File "/home/lianghua/anaconda3/envs/zirui_env/lib/python3.9/site-packages/airflow/dag_processing/manager.py", line 603, in _run_parsing_loop
    DagWarning.purge_inactive_dag_warnings()
  File "/home/lianghua/anaconda3/envs/zirui_env/lib/python3.9/site-packages/airflow/utils/session.py", line 75, in wrapper
    return func(*args, session=session, **kwargs)
  File "/home/lianghua/anaconda3/envs/zirui_env/lib/python3.9/site-packages/airflow/models/dagwarning.py", line 82, in purge_inactive_dag_warnings
    query.delete(synchronize_session=False)
  File "/home/lianghua/anaconda3/envs/zirui_env/lib/python3.9/site-packages/sqlalchemy/orm/query.py", line 3213, in delete
    result = self.session.execute(
  File "/home/lianghua/anaconda3/envs/zirui_env/lib/python3.9/site-packages/sqlalchemy/orm/session.py", line 1712, in execute
    result = conn._execute_20(statement, params or {}, execution_options)
  File "/home/lianghua/anaconda3/envs/zirui_env/lib/python3.9/site-packages/sqlalchemy/engine/base.py", line 1705, in _execute_20
    return meth(self, args_10style, kwargs_10style, execution_options)
  File "/home/lianghua/anaconda3/envs/zirui_env/lib/python3.9/site-packages/sqlalchemy/sql/elements.py", line 333, in _execute_on_connection
    return connection._execute_clauseelement(
  File "/home/lianghua/anaconda3/envs/zirui_env/lib/python3.9/site-packages/sqlalchemy/engine/base.py", line 1572, in _execute_clauseelement
    ret = self._execute_context(
  File "/home/lianghua/anaconda3/envs/zirui_env/lib/python3.9/site-packages/sqlalchemy/engine/base.py", line 1806, in _execute_context
    self._handle_dbapi_exception(
  File "/home/lianghua/anaconda3/envs/zirui_env/lib/python3.9/site-packages/sqlalchemy/engine/base.py", line 2124, in _handle_dbapi_exception
    util.raise_(
  File "/home/lianghua/anaconda3/envs/zirui_env/lib/python3.9/site-packages/sqlalchemy/util/compat.py", line 208, in raise_
    raise exception
  File "/home/lianghua/anaconda3/envs/zirui_env/lib/python3.9/site-packages/sqlalchemy/engine/base.py", line 1800, in _execute_context
    context = constructor(
  File "/home/lianghua/anaconda3/envs/zirui_env/lib/python3.9/site-packages/sqlalchemy/engine/default.py", line 1019, in _init_compiled
    self.cursor = self.create_cursor()
  File "/home/lianghua/anaconda3/envs/zirui_env/lib/python3.9/site-packages/sqlalchemy/engine/default.py", line 1390, in create_cursor
    return self.create_default_cursor()
  File "/home/lianghua/anaconda3/envs/zirui_env/lib/python3.9/site-packages/sqlalchemy/engine/default.py", line 1393, in create_default_cursor
    return self._dbapi_connection.cursor()
  File "/home/lianghua/anaconda3/envs/zirui_env/lib/python3.9/site-packages/sqlalchemy/pool/base.py", line 1099, in cursor
    return self.dbapi_connection.cursor(*args, **kwargs)
  File "/home/lianghua/anaconda3/envs/zirui_env/lib/python3.9/site-packages/mysql/connector/connection_cext.py", line 622, in cursor
    raise OperationalError("MySQL Connection not available.")
sqlalchemy.exc.OperationalError: (mysql.connector.errors.OperationalError) MySQL Connection not available.
[SQL: DELETE FROM dag_warning USING dag_warning, dag WHERE dag_warning.dag_id = dag.dag_id AND dag.is_active = false]
[parameters: [{}]]
(Background on this error at: https://sqlalche.me/e/14/e3q8)
JAVA_HOME is not set
JAVA_HOME is not set
JAVA_HOME is not set
JAVA_HOME is not set
JAVA_HOME is not set
JAVA_HOME is not set
JAVA_HOME is not set
JAVA_HOME is not set
JAVA_HOME is not set
JAVA_HOME is not set
JAVA_HOME is not set
JAVA_HOME is not set
JAVA_HOME is not set
JAVA_HOME is not set
JAVA_HOME is not set
JAVA_HOME is not set
JAVA_HOME is not set
JAVA_HOME is not set
JAVA_HOME is not set
JAVA_HOME is not set
JAVA_HOME is not set
JAVA_HOME is not set
JAVA_HOME is not set
JAVA_HOME is not set
JAVA_HOME is not set
JAVA_HOME is not set
JAVA_HOME is not set
JAVA_HOME is not set
JAVA_HOME is not set
JAVA_HOME is not set
JAVA_HOME is not set
JAVA_HOME is not set
JAVA_HOME is not set
JAVA_HOME is not set
JAVA_HOME is not set
JAVA_HOME is not set
JAVA_HOME is not set
JAVA_HOME is not set
JAVA_HOME is not set
JAVA_HOME is not set
JAVA_HOME is not set
JAVA_HOME is not set
JAVA_HOME is not set
JAVA_HOME is not set
JAVA_HOME is not set
JAVA_HOME is not set
JAVA_HOME is not set
JAVA_HOME is not set
JAVA_HOME is not set
JAVA_HOME is not set
JAVA_HOME is not set
JAVA_HOME is not set
JAVA_HOME is not set
JAVA_HOME is not set
JAVA_HOME is not set
JAVA_HOME is not set
JAVA_HOME is not set
JAVA_HOME is not set
JAVA_HOME is not set
JAVA_HOME is not set
JAVA_HOME is not set
JAVA_HOME is not set
JAVA_HOME is not set
JAVA_HOME is not set
JAVA_HOME is not set
JAVA_HOME is not set
JAVA_HOME is not set
JAVA_HOME is not set
JAVA_HOME is not set
JAVA_HOME is not set
JAVA_HOME is not set
JAVA_HOME is not set
JAVA_HOME is not set
JAVA_HOME is not set
JAVA_HOME is not set
JAVA_HOME is not set
JAVA_HOME is not set
JAVA_HOME is not set
JAVA_HOME is not set
JAVA_HOME is not set
JAVA_HOME is not set
JAVA_HOME is not set
JAVA_HOME is not set
JAVA_HOME is not set
JAVA_HOME is not set
JAVA_HOME is not set
JAVA_HOME is not set
JAVA_HOME is not set
JAVA_HOME is not set
JAVA_HOME is not set
JAVA_HOME is not set
JAVA_HOME is not set
JAVA_HOME is not set
JAVA_HOME is not set
JAVA_HOME is not set
JAVA_HOME is not set
JAVA_HOME is not set
JAVA_HOME is not set
JAVA_HOME is not set
JAVA_HOME is not set
JAVA_HOME is not set
JAVA_HOME is not set
JAVA_HOME is not set
JAVA_HOME is not set
JAVA_HOME is not set
JAVA_HOME is not set
JAVA_HOME is not set
JAVA_HOME is not set
JAVA_HOME is not set
JAVA_HOME is not set
JAVA_HOME is not set
JAVA_HOME is not set
JAVA_HOME is not set
JAVA_HOME is not set
JAVA_HOME is not set
JAVA_HOME is not set
JAVA_HOME is not set
JAVA_HOME is not set
JAVA_HOME is not set
JAVA_HOME is not set
JAVA_HOME is not set
JAVA_HOME is not set
JAVA_HOME is not set
JAVA_HOME is not set
JAVA_HOME is not set
JAVA_HOME is not set
JAVA_HOME is not set
